Workbook

Sheet Historicals
A1: The Procter & Gamble Company (NYSE: PG) - Historical Financials
A2: $ in millions except per-share data. Fiscal years end June 30 (FY2026 = year ended June 30, 2026). Yahoo Finance returns four years for PG.
A4: Fiscal year ended June 30, | B4: FY2023 | C4: FY2024 | D4: FY2025 | E4: FY2026 | G4: Source / note
A6: INCOME STATEMENT
A7: Net sales | B7: 82006 | C7: 84039 | D7: 84284 | E7: 87032 | G7: Yahoo Finance (yfinance), PG annual statements, 9/15/2026
A8: Cost of products sold | B8: 42760 | C8: 40848 | D8: 41164 | E8: 43362 | G8: Yahoo Finance (yfinance), PG annual statements, 9/15/2026
A9: Gross profit | B9: =B7-B8 -> 39246 | C9: =C7-C8 -> 43191 | D9: =D7-D8 -> 43120 | E9: =E7-E8 -> 43670
A10: Selling, general and administrative expense | B10: 21112 | C10: 24646 | D10: 22669 | E10: 23922 | G10: Derived: gross profit less operating income
A11: Operating income (EBIT) | B11: =B9-B10 -> 18134 | C11: =C9-C10 -> 18545 | D11: =D9-D10 -> 20451 | E11: =E9-E10 -> 19748
A13: Memo: depreciation and amortisation (included in costs above) | B13: 2714 | C13: 2896 | D13: 2847 | E13: 3160 | G13: Yahoo Finance (yfinance), PG annual statements, 9/15/2026
A14: EBITDA | B14: =B11+B13 -> 20848 | C14: =C11+C13 -> 21441 | D14: =D11+D13 -> 23298 | E14: =E11+E13 -> 22908
A16: Interest and other non-operating income/(expense), net | B16: 219 | C16: 216 | D16: -284 | E16: 629 | G16: Derived: pretax income less operating income
A17: Pretax income | B17: =B11+B16 -> 18353 | C17: =C11+C16 -> 18761 | D17: =D11+D16 -> 20167 | E17: =E11+E16 -> 20377
A18: Income tax provision | B18: 3615 | C18: 3787 | D18: 4102 | E18: 4233 | G18: Yahoo Finance (yfinance), PG annual statements, 9/15/2026
A19: Consolidated net income | B19: =B17-B18 -> 14738 | C19: =C17-C18 -> 14974 | D19: =D17-D18 -> 16065 | E19: =E17-E18 -> 16144
A20: Less: net earnings attributable to noncontrolling interest | B20: 367 | C20: 379 | D20: 383 | E20: 390 | G20: Derived
A21: Net earnings attributable to Procter & Gamble | B21: =B19-B20 -> 14371 | C21: =C19-C20 -> 14595 | D21: =D19-D20 -> 15682 | E21: =E19-E20 -> 15754
A22: Diluted weighted average shares outstanding | B22: 2484 | C22: 2472 | D22: 2454 | E22: 2422 | G22: Yahoo Finance (yfinance), PG annual statements, 9/15/2026
A23: Diluted earnings per share | B23: =B21/B22 -> 5.7854267 | C23: =C21/C22 -> 5.9041262 | D23: =D21/D22 -> 6.390383 | E23: =E21/E22 -> 6.5045417
A25: BALANCE SHEET
A26: Cash and cash equivalents | B26: 8246 | C26: 9482 | D26: 9556 | E26: 9942 | G26: Yahoo Finance (yfinance), PG annual statements, 9/15/2026
A27: Accounts receivable | B27: 5471 | C27: 6118 | D27: 6185 | E27: 6056 | G27: Yahoo Finance (yfinance), PG annual statements, 9/15/2026
A28: Inventories | B28: 7073 | C28: 7016 | D28: 7551 | E28: 8170 | G28: Yahoo Finance (yfinance), PG annual statements, 9/15/2026
A29: Other current assets | B29: 1858 | C29: 2093 | D29: 2100 | E29: 2040 | G29: Yahoo Finance (yfinance), PG annual statements, 9/15/2026
A30: Total current assets | B30: =SUM(B26:B29) -> 22648 | C30: =SUM(C26:C29) -> 24709 | D30: =SUM(D26:D29) -> 25392 | E30: =SUM(E26:E29) -> 26208
A31: Property, plant and equipment, net | B31: 21909 | C31: 22152 | D31: 23897 | E31: 25360 | G31: Yahoo Finance (yfinance), PG annual statements, 9/15/2026; the depreciable base
A32: Goodwill | B32: 40659 | C32: 40303 | D32: 41650 | E32: 41276 | G32: Yahoo Finance (yfinance), PG annual statements, 9/15/2026
A33: Other intangible assets, net | B33: 23783 | C33: 22047 | D33: 21910 | E33: 21444 | G33: Yahoo Finance (yfinance), PG annual statements, 9/15/2026; largely indefinite-lived brands
A34: Other non-current assets | B34: =B35-B30-B31-B32-B33 -> 11830 | C34: =C35-C30-C31-C32-C33 -> 13159 | D34: =D35-D30-D31-D32-D33 -> 12382 | E34: =E35-E30-E31-E32-E33 -> 12233 | G34: Plug to total assets
A35: Total assets | B35: 120829 | C35: 122370 | D35: 125231 | E35: 126521 | G35: Yahoo Finance (yfinance), PG annual statements, 9/15/2026
A37: Accounts payable | B37: 14598 | C37: 15364 | D37: 15227 | E37: 16306 | G37: Yahoo Finance (yfinance), PG annual statements, 9/15/2026
A38: Accrued and other current liabilities | B38: 10707 | C38: 10829 | D38: 11064 | E38: 10845 | G38: Plug: total current liabilities less the other current lines
A39: Debt due within one year | B39: 10229 | C39: 7191 | D39: 9512 | E39: 11297 | G39: Yahoo Finance (yfinance), PG annual statements, 9/15/2026
A40: Current portion of lease obligations | B40: 222 | C40: 243 | D40: 255 | E40: 246 | G40: Yahoo Finance (yfinance), PG annual statements, 9/15/2026
A41: Total current liabilities | B41: =SUM(B37:B40) -> 35756 | C41: =SUM(C37:C40) -> 33627 | D41: =SUM(D37:D40) -> 36058 | E41: =SUM(E37:E40) -> 38694
A42: Long-term debt | B42: 24378 | C42: 25269 | D42: 24995 | E42: 22842 | G42: Yahoo Finance (yfinance), PG annual statements, 9/15/2026
A43: Long-term lease obligations | B43: 595 | C43: 666 | D43: 701 | E43: 641 | G43: Yahoo Finance (yfinance), PG annual statements, 9/15/2026
A44: Deferred income taxes and other non-current liabilities | B44: =B45-B41-B42-B43 -> 13035 | C44: =C45-C41-C42-C43 -> 12250 | D44: =D45-D41-D42-D43 -> 11193 | E44: =E45-E41-E42-E43 -> 10033 | G44: Plug to total liabilities
A45: Total liabilities | B45: =B35-B46-B47 -> 73764 | C45: =C35-C46-C47 -> 71812 | D45: =D35-D46-D47 -> 72947 | E45: =E35-E46-E47 -> 72210
A46: Noncontrolling interest | B46: 288 | C46: 272 | D46: 272 | E46: 230 | G46: Yahoo Finance (yfinance), PG annual statements, 9/15/2026
...

Sheet Ratios
A1: Historical Ratio Analysis
A2: The three ratios the forecast needs. Ratios against next year sales stop at FY2025; ratios on the opening balance start at FY2024.
A4: Fiscal year ended June 30, | B4: FY2023 | C4: FY2024 | D4: FY2025 | E4: FY2026 | F4: Average | H4: Comment
A6: GROWTH AND MARGINS
A7: Net sales growth | B7: n/a | C7: =Historicals!C7/Historicals!B7-1 -> 0.024790869 | D7: =Historicals!D7/Historicals!C7-1 -> 0.0029153131 | E7: =Historicals!E7/Historicals!D7-1 -> 0.032604053 | F7: =AVERAGE(C7:E7) -> 0.020103412 | H7: Slow: 2.5%, 0.3%, 3.3%.
A8: Gross margin | B8: =Historicals!B9/Historicals!B7 -> 0.47857474 | C8: =Historicals!C9/Historicals!C7 -> 0.51393996 | D8: =Historicals!D9/Historicals!D7 -> 0.51160363 | E8: =Historicals!E9/Historicals!E7 -> 0.50176946 | F8: =AVERAGE(B8:E8) -> 0.50147195
A9: Operating margin (EBIT) | B9: =Historicals!B11/Historicals!B7 -> 0.22113016 | C9: =Historicals!C11/Historicals!C7 -> 0.22067135 | D9: =Historicals!D11/Historicals!D7 -> 0.24264392 | E9: =Historicals!E11/Historicals!E7 -> 0.22690505 | F9: =AVERAGE(B9:E9) -> 0.22783762 | H9: FY2024 is reduced by a $1,341mm impairment charge; without it the margin is 23.7%.
A10: EBITDA margin | B10: =Historicals!B14/Historicals!B7 -> 0.2542253 | C10: =Historicals!C14/Historicals!C7 -> 0.25513155 | D10: =Historicals!D14/Historicals!D7 -> 0.27642257 | E10: =Historicals!E14/Historicals!E7 -> 0.26321353 | F10: =AVERAGE(B10:E10) -> 0.26224824
A11: Net margin | B11: =Historicals!B21/Historicals!B7 -> 0.17524327 | C11: =Historicals!C21/Historicals!C7 -> 0.17366937 | D11: =Historicals!D21/Historicals!D7 -> 0.18606141 | E11: =Historicals!E21/Historicals!E7 -> 0.18101388 | F11: =AVERAGE(B11:E11) -> 0.17899698
A12: Effective tax rate | B12: =Historicals!B18/Historicals!B17 -> 0.19697052 | C12: =Historicals!C18/Historicals!C17 -> 0.20185491 | D12: =Historicals!D18/Historicals!D17 -> 0.2034016 | E12: =Historicals!E18/Historicals!E17 -> 0.20773421 | F12: =AVERAGE(B12:E12) -> 0.20249031 | H12: 19.7% to 20.8%. Notably stable.
A14: THE THREE FORECAST RATIOS
A15: Net PP&E as % of next year net sales (k) | B15: =Historicals!B31/Historicals!C7 -> 0.26070039 | C15: =Historicals!C31/Historicals!D7 -> 0.26282568 | D15: =Historicals!D31/Historicals!E7 -> 0.27457717 | E15: n/a | F15: =AVERAGE(B15:D15) -> 0.26603441 | H15: Rising: 26.1%, 26.3%, 27.5%. Needs the following year, so FY2026 drops out.
A16: Depreciation as % of opening net PP&E (d) | B16: n/a | C16: =Historicals!C13/Historicals!B31 -> 0.13218312 | D16: =Historicals!D13/Historicals!C31 -> 0.12852113 | E16: =Historicals!E13/Historicals!D31 -> 0.13223417 | F16: =AVERAGE(C16:E16) -> 0.13097947 | H16: 13.22%, 12.85%, 13.22%. Needs the prior year, so FY2023 drops out.
A17: Net working capital as % of next year net sales (w) | B17: =Historicals!B55/Historicals!C7 -> -0.12973738 | C17: =Historicals!C55/Historicals!D7 -> -0.13010773 | D17: =Historicals!D55/Historicals!E7 -> -0.12012823 | E17: n/a | F17: =AVERAGE(B17:D17) -> -0.12665778 | H17: Around -12.7%. PG is funded by its suppliers, so growth releases cash.
A18: Implied average depreciable life (years) | B18: n/a | C18: =Historicals!B31/Historicals!C13 -> 7.5652624 | D18: =Historicals!C31/Historicals!D13 -> 7.7808219 | E18: =Historicals!D31/Historicals!E13 -> 7.5623418 | F18: =AVERAGE(C18:E18) -> 7.636142 | H18: About 7.7 years.
A20: CAPITAL SPENDING AND RETURNS
A21: Capital expenditures % of net sales | B21: =Historicals!B65/Historicals!B7 -> 0.037338731 | C21: =Historicals!C65/Historicals!C7 -> 0.039529266 | D21: =Historicals!D65/Historicals!D7 -> 0.044765317 | E21: =Historicals!E65/Historicals!E7 -> 0.050659528 | F21: =AVERAGE(B21:E21) -> 0.043073211 | H21: Rising: 3.7% to 5.1%.
A22: Capex / depreciation | B22: =Historicals!B65/Historicals!B13 -> 1.128224 | C22: =Historicals!C65/Historicals!C13 -> 1.1470994 | D22: =Historicals!D65/Historicals!D13 -> 1.3252547 | E22: =Historicals!E65/Historicals!E13 -> 1.3952532 | F22: =AVERAGE(B22:E22) -> 1.2489578
A23: Goodwill and intangibles % of total assets | B23: =Historicals!B57/Historicals!B35 -> 0.53333223 | C23: =Historicals!C57/Historicals!C35 -> 0.50952031 | D23: =Historicals!D57/Historicals!D35 -> 0.50754206 | E23: =Historicals!E57/Historicals!E35 -> 0.49572798 | F23: =AVERAGE(B23:E23) -> 0.51153065 | H23: Half the balance sheet, and none of it depreciates.
A24: Net other non-current assets % of net sales | B24: =Historicals!B58/Historicals!B7 -> -0.014694047 | C24: =Historicals!C58/Historicals!C7 -> 0.010816407 | D24: =Historicals!D58/Historicals!D7 -> 0.014107067 | E24: =Historicals!E58/Historicals!E7 -> 0.025278059 | F24: =AVERAGE(B24:E24) -> 0.0088768713
A25: NOPAT (EBIT after tax), $mm | B25: =Historicals!B11*(1-Historicals!B18/Historicals!B17) -> 14562.137 | C25: =Historicals!C11*(1-Historicals!C18/Historicals!C17) -> 14801.601 | D25: =Historicals!D11*(1-Historicals!D18/Historicals!D17) -> 16291.234 | E25: =Historicals!E11*(1-Historicals!E18/Historicals!E17) -> 15645.665 | F25: =AVERAGE(B25:E25) -> 15325.159
A26: Return on invested capital | B26: =B25/Historicals!B59 -> 0.19614154 | C26: =C25/Historicals!C59 -> 0.19882599 | D26: =D25/Historicals!D59 -> 0.20835178 | E26: =E25/Historicals!E59 -> 0.19706108 | F26: =AVERAGE(B26:E26) -> 0.2000951 | H26: NOPAT / invested capital. Goodwill in the denominator holds it down.
A27: Return on equity | B27: =Historicals!B21/Historicals!B47 -> 0.30722364 | C27: =Historicals!C21/Historicals!C47 -> 0.29023983 | D27: =Historicals!D21/Historicals!D47 -> 0.30150734 | E27: =Historicals!E21/Historicals!E47 -> 0.29130379 | F27: =AVERAGE(B27:E27) -> 0.29756865
A28: Total debt / EBITDA | B28: =Historicals!B52/Historicals!B14 -> 1.6991558 | C28: =Historicals!C52/Historicals!C14 -> 1.5563173 | D28: =Historicals!D52/Historicals!D14 -> 1.5221478 | E28: =Historicals!E52/Historicals!E14 -> 1.5289855 | F28: =AVERAGE(B28:E28) -> 1.5766516
A29: Free cash flow conversion (FCF / net earnings) | B29: =Historicals!B66/Historicals!B21 -> 0.95929302 | C29: =Historicals!C66/Historicals!C21 -> 1.1321686 | D29: =Historicals!D66/Historicals!D21 -> 0.89554904 | E29: =Historicals!E66/Historicals!E21 -> 0.9614701 | F29: =AVERAGE(B29:E29) -> 0.98712018
A31: PG lease obligations total under $1bn, against $22bn at Walmart, so the finance/operating lease split does not move any of these ratios.
