Workbook

Sheet Summary
A1: Walmart Inc. (WMT) - Two-Stage DCF Valuation Summary
A2: Prepared September 15, 2026. Financial data from Yahoo Finance, with SEC EDGAR for FY2022 and for the debt, lease and PP&E detail.
A4: VALUATION RESULT
B5: Perpetuity growth | C5: Exit multiple
A6: Enterprise value ($mm) | B6: =DCF!C71 -> 474597.81 | C6: =DCF!D71 -> 554571.33
A7: Bridge: net debt, other long-term items and minority interest ($mm) | B7: =SUM(DCF!C72:C75) -> -49805 | C7: =SUM(DCF!D72:D75) -> -49805
A8: Equity value ($mm) | B8: =DCF!C76 -> 424792.81 | C8: =DCF!D76 -> 504766.33
A9: Diluted shares outstanding (mm) | B9: =DCF!C77 -> 8022 | C9: =DCF!D77 -> 8022
A10: Implied value per share | B10: =DCF!C78 -> 52.95348 | C10: =DCF!D78 -> 62.922754 | D10: The two methods differ only in how the terminal value is set.
A11: Current share price | B11: =WACC!B5 -> 108.09 | C11: =WACC!B5 -> 108.09
A12: Implied upside / (downside) | B12: =DCF!C81 -> -0.51009826 | C12: =DCF!D81 -> -0.41786702
A14: KEY INPUTS
A15: Weighted average cost of capital | B15: =WACC!B33 -> 0.077223333 | D15: CAPM cost of equity 7.95% on a 4.97% risk-free rate and 0.595 beta.
A16: Terminal growth rate | B16: =DCF!C59 -> 0.03 | D16: FY2031 already grows at this rate, so it is the steady-state year.
A17: Net PP&E % of next year revenue (k) | B17: =DCF!C10 -> 0.19 | D17: FY2025 actual 17.7%. Drives capex, which is the residual.
A18: Depreciation % of opening net PP&E (d) | B18: =DCF!C11 -> 0.112 | D18: FY2023-FY2026 actuals sat in an 11.07-11.26% band.
A19: Net working capital % of next year revenue (w) | B19: =DCF!C13 -> -0.0275 | D19: FY2022-FY2025 averaged -2.7%.
A20: FY2031 operating margin | B20: =DCF!G8 -> 0.044 | D20: Versus 4.18% in FY2026.
A21: FY2027-FY2031 implied capex % of revenue | B21: =AVERAGE(DCF!C29:G29) -> 0.025947005 | D21: Output, not an input. FY2022-FY2026 actuals ran 2.3% to 3.7%.
A23: WHAT THE MARKET IS PRICING
A24: Enterprise value at the current share price ($mm) | B24: =WACC!B12 -> 914456.98
A25: Enterprise value / FY2026 EBITDA at market | B25: =WACC!B12/Historicals!F14 -> 20.769896
A26: Price / FY2026 diluted earnings per share | B26: =WACC!B5/Historicals!F24 -> 39.606175
A27: Enterprise value / FY2026 free cash flow at market | B27: =WACC!B12/Historicals!F71 -> 61.278361
A28: Perpetual growth rate implied by the current price | B28: =Sensitivity!B25 -> 0.054737149 | D28: Solved from the reverse DCF on the Sensitivity sheet.
A30: HOW THIS MODEL IS BUILT
A31: - Three ratios drive the forecast, following the worked example earlier in the course: net PP&E is k times next year revenue, depreciation is d times the opening net PP&E balance, and net working capital is w times next year revenue. Capital expenditure is the residual that reconciles the opening and closing PP&E balances.
A32: - The forecast is built on invested capital, not total assets. Total assets mixes depreciating operating capital, non-depreciating operating capital and financial items, so no single ratio fits it and depreciation has no coherent denominator.
A33: - Every balance sheet item belongs in exactly one of two places: invested capital, if it produces the operating cash flows being discounted, or the enterprise-value-to-equity bridge, if it does not. Never both, and never neither.
A34: - Goodwill and the netted other long-term items are held flat, because neither can be forecast meaningfully, and both are carried in the bridge at book value.
A35: - Leases are split. Finance leases sit inside the depreciable PP&E base and inside debt, because they depreciate and carry interest. Operating leases are excluded from both, and their rent stays inside EBIT.
A36: - The operating build of invested capital ties exactly to net debt plus noncontrolling interest plus equity in all five historical years, so the balance sheet articulates and the forecast inherits that discipline.
A37: - Free cash flow is shown two ways and reconciled: NOPAT plus depreciation less capex and working capital, and NOPAT less the increase in invested capital. They agree by construction.
A38: - Colour key: blue = input, black = formula, green = link to another sheet, yellow = the assumptions that drive the answer.

Sheet Historicals
A1: Walmart Inc. (NYSE: WMT) - Historical Financials
A2: $ in millions except per-share data. Fiscal years end January 31 (FY2026 = year ended January 31, 2026).
A4: Fiscal year ended January 31, | B4: FY2022 | C4: FY2023 | D4: FY2024 | E4: FY2025 | F4: FY2026 | G4: Source / note
A6: INCOME STATEMENT
A7: Revenue | B7: 572754 | C7: 611289 | D7: 648125 | E7: 680985 | F7: 713163 | G7: Yahoo Finance (yfinance), WMT annual statements, 9/15/2026
A8: Cost of revenue | B8: 429000 | C8: 463721 | D8: 490142 | E8: 511753 | F8: 535395 | G8: Yahoo Finance (yfinance), WMT annual statements, 9/15/2026
A9: Gross profit | B9: =B7-B8 -> 143754 | C9: =C7-C8 -> 147568 | D9: =D7-D8 -> 157983 | E9: =E7-E8 -> 169232 | F9: =F7-F8 -> 177768
A10: Operating, selling, general and administrative expenses | B10: 117812 | C10: 127140 | D10: 130971 | E10: 139884 | F10: 147943 | G10: Yahoo Finance (yfinance), WMT annual statements, 9/15/2026
A11: Operating income (EBIT) | B11: =B9-B10 -> 25942 | C11: =C9-C10 -> 20428 | D11: =D9-D10 -> 27012 | E11: =E9-E10 -> 29348 | F11: =F9-F10 -> 29825
A13: Memo: depreciation and amortisation (included in costs above) | B13: 10658 | C13: 10945 | D13: 11853 | E13: 12973 | F13: 14203 | G13: Yahoo Finance (yfinance), WMT annual statements, 9/15/2026
A14: EBITDA | B14: =B11+B13 -> 36600 | C14: =C11+C13 -> 31373 | D14: =D11+D13 -> 38865 | E14: =E11+E13 -> 42321 | F14: =F11+F13 -> 44028
A16: Interest expense | B16: 1674 | C16: 2128 | D16: 2683 | E16: 2728 | F16: 2799 | G16: Yahoo Finance (yfinance), WMT annual statements, 9/15/2026
A17: Interest income and other gains/(losses), net | B17: -5572 | C17: -1284 | D17: -2481 | E17: -311 | F17: 2443 | G17: Yahoo Finance (yfinance), WMT annual statements, 9/15/2026
A18: Pretax income | B18: =B11-B16+B17 -> 18696 | C18: =C11-C16+C17 -> 17016 | D18: =D11-D16+D17 -> 21848 | E18: =E11-E16+E17 -> 26309 | F18: =F11-F16+F17 -> 29469
A19: Income tax provision | B19: 4756 | C19: 5724 | D19: 5578 | E19: 6152 | F19: 7199 | G19: Yahoo Finance (yfinance), WMT annual statements, 9/15/2026
A20: Consolidated net income | B20: =B18-B19 -> 13940 | C20: =C18-C19 -> 11292 | D20: =D18-D19 -> 16270 | E20: =E18-E19 -> 20157 | F20: =F18-F19 -> 22270
A21: Less: net income attributable to noncontrolling interest | B21: 267 | C21: -388 | D21: 759 | E21: 721 | F21: 377 | G21: Yahoo Finance (yfinance), WMT annual statements, 9/15/2026
A22: Net income attributable to Walmart | B22: =B20-B21 -> 13673 | C22: =C20-C21 -> 11680 | D22: =D20-D21 -> 15511 | E22: =E20-E21 -> 19436 | F22: =F20-F21 -> 21893
A23: Diluted weighted average shares outstanding | B23: 8415 | C23: 8202 | D23: 8109 | E23: 8081 | F23: 8022 | G23: Yahoo Finance (yfinance), WMT annual statements, 9/15/2026; FY2022 restated for the 3-for-1 split (Feb 2024)
A24: Diluted earnings per share | B24: =B22/B23 -> 1.6248366 | C24: =C22/C23 -> 1.4240429 | D24: =D22/D23 -> 1.9128129 | E24: =E22/E23 -> 2.4051479 | F24: =F22/F23 -> 2.7291199
A26: BALANCE SHEET
A27: Cash and cash equivalents | B27: 14760 | C27: 8625 | D27: 9867 | E27: 9037 | F27: 10727 | G27: Yahoo Finance (yfinance), WMT annual statements, 9/15/2026
A28: Receivables, net | B28: 8280 | C28: 7933 | D28: 8796 | E28: 9975 | F28: 11172 | G28: Yahoo Finance (yfinance), WMT annual statements, 9/15/2026
A29: Inventories | B29: 56511 | C29: 56576 | D29: 54892 | E29: 56435 | F29: 58851 | G29: Yahoo Finance (yfinance), WMT annual statements, 9/15/2026
A30: Other current assets | B30: 1519 | C30: 2521 | D30: 3322 | E30: 4011 | F30: 4124 | G30: Yahoo Finance (yfinance), WMT annual statements, 9/15/2026
A31: Total current assets | B31: =SUM(B27:B30) -> 81070 | C31: =SUM(C27:C30) -> 75655 | D31: =SUM(D27:D30) -> 76877 | E31: =SUM(E27:E30) -> 79458 | F31: =SUM(F27:F30) -> 84874
A32: Property and equipment incl. finance lease ROU assets, net | B32: 98866 | C32: 105679 | D32: 116665 | E32: 126105 | F32: 142206 | G32: SEC EDGAR XBRL companyfacts, CIK 0000104169; the depreciable base
A33: Operating lease right-of-use assets | B33: 13758 | C33: 13555 | D33: 13673 | E33: 13599 | F33: 14750 | G33: SEC EDGAR XBRL companyfacts, CIK 0000104169
A34: Goodwill | B34: 29014 | C34: 28174 | D34: 28113 | E34: 28792 | F34: 28735 | G34: Yahoo Finance (yfinance), WMT annual statements, 9/15/2026
A35: Other long-term assets | B35: =B36-B31-B32-B33-B34 -> 22152 | C35: =C36-C31-C32-C33-C34 -> 20134 | D35: =D36-D31-D32-D33-D34 -> 17071 | E35: =E36-E31-E32-E33-E34 -> 12869 | F35: =F36-F31-F32-F33-F34 -> 14103 | G35: Plug to total assets
A36: Total assets | B36: 244860 | C36: 243197 | D36: 252399 | E36: 260823 | F36: 284668 | G36: Yahoo Finance (yfinance), WMT annual statements, 9/15/2026
A38: Accounts payable | B38: 55261 | C38: 53742 | D38: 56812 | E38: 58666 | F38: 63061 | G38: Yahoo Finance (yfinance), WMT annual statements, 9/15/2026
A39: Accrued and other current liabilities | B39: 26911 | C39: 31853 | D39: 29066 | E39: 29953 | F39: 31783 | G39: Yahoo Finance (yfinance), WMT annual statements, 9/15/2026
A40: Short-term borrowings and current portion of long-term debt | B40: 3213 | C40: 4563 | D40: 4325 | E40: 5666 | F40: 10138 | G40: SEC EDGAR XBRL companyfacts, CIK 0000104169
A41: Current portion of finance lease obligations | B41: 511 | C41: 567 | D41: 725 | E41: 800 | F41: 856 | G41: SEC EDGAR XBRL companyfacts, CIK 0000104169
A42: Current portion of operating lease liabilities | B42: 1483 | C42: 1473 | D42: 1487 | E42: 1499 | F42: 1631 | G42: SEC EDGAR XBRL companyfacts, CIK 0000104169
A43: Total current liabilities | B43: =SUM(B38:B42) -> 87379 | C43: =SUM(C38:C42) -> 92198 | D43: =SUM(D38:D42) -> 92415 | E43: =SUM(E38:E42) -> 96584 | F43: =SUM(F38:F42) -> 107469
A44: Long-term debt | B44: 34864 | C44: 34649 | D44: 36132 | E44: 33401 | F44: 34624 | G44: SEC EDGAR XBRL companyfacts, CIK 0000104169
A45: Long-term finance lease obligations | B45: 4243 | C45: 4843 | D45: 5709 | E45: 5923 | F45: 5905 | G45: SEC EDGAR XBRL companyfacts, CIK 0000104169
A46: Long-term operating lease liabilities | B46: 13009 | C46: 12828 | D46: 12943 | E46: 12825 | F46: 13941 | G46: SEC EDGAR XBRL companyfacts, CIK 0000104169
...

Sheet Ratios
A1: Historical Ratio Analysis
A2: The drivers extrapolated in the DCF. FY2023 operating margin is depressed by opioid legal charges.
A4: Fiscal year ended January 31, | B4: FY2022 | C4: FY2023 | D4: FY2024 | E4: FY2025 | F4: FY2026 | G4: 5-yr avg | H4: 3-yr avg | I4: Comment
A6: GROWTH
A7: Revenue growth | B7: n/a | C7: =Historicals!C7/Historicals!B7-1 -> 0.067280194 | D7: =Historicals!D7/Historicals!C7-1 -> 0.06025955 | E7: =Historicals!E7/Historicals!D7-1 -> 0.050700096 | F7: =Historicals!F7/Historicals!E7-1 -> 0.047252142 | G7: =AVERAGE(C7:F7) -> 0.056372996 | H7: =AVERAGE(D7:F7) -> 0.052737263 | I7: Decelerating: 6.7% to 4.7% over four years.
A8: EBITDA growth | B8: n/a | C8: =Historicals!C14/Historicals!B14-1 -> -0.14281421 | D8: =Historicals!D14/Historicals!C14-1 -> 0.23880407 | E8: =Historicals!E14/Historicals!D14-1 -> 0.088923196 | F8: =Historicals!F14/Historicals!E14-1 -> 0.040334586 | G8: =AVERAGE(C8:F8) -> 0.05631191 | H8: =AVERAGE(D8:F8) -> 0.12268728
A9: Net income growth | B9: n/a | C9: =Historicals!C22/Historicals!B22-1 -> -0.14576172 | D9: =Historicals!D22/Historicals!C22-1 -> 0.32799658 | E9: =Historicals!E22/Historicals!D22-1 -> 0.25304623 | F9: =Historicals!F22/Historicals!E22-1 -> 0.1264149 | G9: =AVERAGE(C9:F9) -> 0.140424 | H9: =AVERAGE(D9:F9) -> 0.23581923
A11: MARGINS AND TAX
A12: Gross margin | B12: =Historicals!B9/Historicals!B7 -> 0.25098733 | C12: =Historicals!C9/Historicals!C7 -> 0.24140464 | D12: =Historicals!D9/Historicals!D7 -> 0.24375391 | E12: =Historicals!E9/Historicals!E7 -> 0.24851061 | F12: =Historicals!F9/Historicals!F7 -> 0.249267 | G12: =AVERAGE(B12:F12) -> 0.2467847 | H12: =AVERAGE(D12:F12) -> 0.24717717 | I12: Widening on e-commerce, advertising and membership mix.
A13: Operating margin (EBIT) | B13: =Historicals!B11/Historicals!B7 -> 0.045293442 | C13: =Historicals!C11/Historicals!C7 -> 0.033417909 | D13: =Historicals!D11/Historicals!D7 -> 0.041677146 | E13: =Historicals!E11/Historicals!E7 -> 0.043096397 | F13: =Historicals!F11/Historicals!F7 -> 0.041820734 | G13: =AVERAGE(B13:F13) -> 0.041061125 | H13: =AVERAGE(D13:F13) -> 0.042198092 | I13: c.4.2-4.3% excluding the FY2023 charges.
A14: EBITDA margin | B14: =Historicals!B14/Historicals!B7 -> 0.06390178 | C14: =Historicals!C14/Historicals!C7 -> 0.051322697 | D14: =Historicals!D14/Historicals!D7 -> 0.059965284 | E14: =Historicals!E14/Historicals!E7 -> 0.062146743 | F14: =Historicals!F14/Historicals!F7 -> 0.061736237 | G14: =AVERAGE(B14:F14) -> 0.059814548 | H14: =AVERAGE(D14:F14) -> 0.061282755
A15: Net margin | B15: =Historicals!B22/Historicals!B7 -> 0.023872378 | C15: =Historicals!C22/Historicals!C7 -> 0.019107165 | D15: =Historicals!D22/Historicals!D7 -> 0.023932112 | E15: =Historicals!E22/Historicals!E7 -> 0.02854101 | F15: =Historicals!F22/Historicals!F7 -> 0.030698452 | G15: =AVERAGE(B15:F15) -> 0.025230224 | H15: =AVERAGE(D15:F15) -> 0.027723858
A16: Effective tax rate | B16: =Historicals!B19/Historicals!B18 -> 0.25438596 | C16: =Historicals!C19/Historicals!C18 -> 0.33638928 | D16: =Historicals!D19/Historicals!D18 -> 0.25530941 | E16: =Historicals!E19/Historicals!E18 -> 0.23383633 | F16: =Historicals!F19/Historicals!F18 -> 0.24429061 | G16: =AVERAGE(B16:F16) -> 0.26484232 | H16: =AVERAGE(D16:F16) -> 0.24447878 | I16: FY2023 elevated by non-deductible items.
A18: FIXED CAPITAL - THE THREE COURSE RATIOS
A19: Net PP&E as % of next year revenue (k) | B19: =Historicals!B32/Historicals!C7 -> 0.16173365 | C19: =Historicals!C32/Historicals!D7 -> 0.16305342 | D19: =Historicals!D32/Historicals!E7 -> 0.17131802 | E19: =Historicals!E32/Historicals!F7 -> 0.17682493 | F19: n/a | G19: =AVERAGE(B19:E19) -> 0.16823251 | H19: =AVERAGE(D19:E19) -> 0.17407148 | I19: Rising: WMT is carrying more plant per dollar of the sales it serves. The key fixed-capital judgment.
A20: Depreciation as % of opening net PP&E (d) | B20: n/a | C20: =Historicals!C13/Historicals!B32 -> 0.1107054 | D20: =Historicals!D13/Historicals!C32 -> 0.11216041 | E20: =Historicals!E13/Historicals!D32 -> 0.11119873 | F20: =Historicals!F13/Historicals!E32 -> 0.11262837 | G20: =AVERAGE(C20:F20) -> 0.11167323 | H20: =AVERAGE(D20:F20) -> 0.11199584 | I20: 11.07%, 11.22%, 11.12%, 11.26%. Stable enough to hold constant.
A21: Implied average depreciable life (years) | B21: n/a | C21: =Historicals!B32/Historicals!C13 -> 9.0329831 | D21: =Historicals!C32/Historicals!D13 -> 8.9158019 | E21: =Historicals!D32/Historicals!E13 -> 8.9929083 | F21: =Historicals!E32/Historicals!F13 -> 8.878758 | G21: =AVERAGE(C21:F21) -> 8.9551128 | H21: =AVERAGE(D21:F21) -> 8.9291561 | I21: About 8.9 years, consistent across the period.
A22: Capital expenditures % of revenue | B22: =Historicals!B70/Historicals!B7 -> 0.022882424 | C22: =Historicals!C70/Historicals!C7 -> 0.027576155 | D22: =Historicals!D70/Historicals!D7 -> 0.03179325 | E22: =Historicals!E70/Historicals!E7 -> 0.034924411 | F22: =Historicals!F70/Historicals!F7 -> 0.037357519 | G22: =AVERAGE(B22:F22) -> 0.030906752 | H22: =AVERAGE(D22:F22) -> 0.034691726 | I22: Output of the three ratios, not an input. Ran 2.3% to 3.7%.
A23: Capex / depreciation | B23: =Historicals!B70/Historicals!B13 -> 1.2296866 | C23: =Historicals!C70/Historicals!C13 -> 1.5401553 | D23: =Historicals!D70/Historicals!D13 -> 1.7384628 | E23: =Historicals!E70/Historicals!E13 -> 1.8332691 | F23: =Historicals!F70/Historicals!F13 -> 1.8758009 | G23: =AVERAGE(B23:F23) -> 1.643475 | H23: =AVERAGE(D23:F23) -> 1.8158443 | I23: Above 1.0x, so the asset base is still growing.
A26: OTHER COMPONENTS OF INVESTED CAPITAL
A27: Net working capital as % of next year revenue (w) | B27: =Historicals!B59/Historicals!C7 -> -0.025948447 | C27: =Historicals!C59/Historicals!D7 -> -0.028644166 | D27: =Historicals!D59/Historicals!E7 -> -0.027706925 | E27: =Historicals!E59/Historicals!F7 -> -0.025517308 | F27: n/a | G27: =AVERAGE(B27:E27) -> -0.026954211 | H27: =AVERAGE(D27:E27) -> -0.026612116 | I27: Stable near -2.7%: supplier float, so growth releases cash.
A28: Net other long-term assets % of revenue | B28: =Historicals!B63/Historicals!B7 -> 0.015151356 | C28: =Historicals!C63/Historicals!C7 -> 0.008909043 | D28: =Historicals!D63/Historicals!D7 -> 0.0037677917 | E28: =Historicals!E63/Historicals!E7 -> -0.0022452771 | F28: =Historicals!F63/Historicals!F7 -> -0.0034297909 | G28: =AVERAGE(B28:F28) -> 0.0044306246 | H28: =AVERAGE(D28:F28) -> -0.00063575877 | I28: Small. Held flat and carried in the bridge rather than forecast.
A29: Goodwill % of revenue | B29: =Historicals!B34/Historicals!B7 -> 0.050657001 | C29: =Historicals!C34/Historicals!C7 -> 0.046089493 | D29: =Historicals!D34/Historicals!D7 -> 0.043375892 | E29: =Historicals!E34/Historicals!E7 -> 0.042279933 | F29: =Historicals!F34/Historicals!F7 -> 0.040292331 | G29: =AVERAGE(B29:F29) -> 0.04453893 | H29: =AVERAGE(D29:F29) -> 0.041982719 | I29: Does not depreciate. Held flat in an organic forecast.
A30: Operating lease ROU net of lease liabilities % of revenue | B30: =Historicals!B62/Historicals!B7 -> -0.0012815275 | C30: =Historicals!C62/Historicals!C7 -> -0.001220372 | D30: =Historicals!D62/Historicals!D7 -> -0.0011679846 | E30: =Historicals!E62/Historicals!E7 -> -0.0010646343 | F30: =Historicals!F62/Historicals!F7 -> -0.0011526117 | G30: =AVERAGE(B30:F30) -> -0.001177426 | H30: =AVERAGE(D30:F30) -> -0.0011284102 | I30: Near zero: the asset and liability offset, which is why both are excluded.
A32: RETURNS AND LEVERAGE
A33: NOPAT (EBIT after tax), $mm | B33: =Historicals!B11*(1-Historicals!B19/Historicals!B18) -> 19342.719 | C33: =Historicals!C11*(1-Historicals!C19/Historicals!C18) -> 13556.24 | D33: =Historicals!D11*(1-Historicals!D19/Historicals!D18) -> 20115.582 | E33: =Historicals!E11*(1-Historicals!E19/Historicals!E18) -> 22485.371 | F33: =Historicals!F11*(1-Historicals!F19/Historicals!F18) -> 22539.033 | G33: =AVERAGE(B33:F33) -> 19607.789 | H33: =AVERAGE(D33:F33) -> 21713.329
A34: Return on invested capital | B34: =B33/Historicals!B64 -> 0.16124039 | C34: =C33/Historicals!C64 -> 0.11297996 | D34: =D33/Historicals!D64 -> 0.15765181 | E34: =E33/Historicals!E64 -> 0.16724587 | F34: =F33/Historicals!F64 -> 0.15335179 | G34: =AVERAGE(B34:F34) -> 0.15049396 | H34: =AVERAGE(D34:F34) -> 0.15941649 | I34: NOPAT / invested capital, on the operating build above.
A35: Return on equity | B35: =Historicals!B22/Historicals!B50 -> 0.16423432 | C35: =Historicals!C22/Historicals!C50 -> 0.15229552 | D35: =Historicals!D22/Historicals!D50 -> 0.18496083 | E35: =Historicals!E22/Historicals!E50 -> 0.21355191 | F35: =Historicals!F22/Historicals!F50 -> 0.21977173 | G35: =AVERAGE(B35:F35) -> 0.18696286 | H35: =AVERAGE(D35:F35) -> 0.20609482
A36: Total financial debt / EBITDA | B36: =Historicals!B55/Historicals!B14 -> 1.1702459 | C36: =Historicals!C55/Historicals!C14 -> 1.4223058 | D36: =Historicals!D55/Historicals!D14 -> 1.2065097 | E36: =Historicals!E55/Historicals!E14 -> 1.0819688 | F36: =Historicals!F55/Historicals!F14 -> 1.1702326 | G36: =AVERAGE(B36:F36) -> 1.2102526 | H36: =AVERAGE(D36:F36) -> 1.1529037
A37: EBITDA / interest expense | B37: =Historicals!B14/Historicals!B16 -> 21.863799 | C37: =Historicals!C14/Historicals!C16 -> 14.742951 | D37: =Historicals!D14/Historicals!D16 -> 14.48565 | E37: =Historicals!E14/Historicals!E16 -> 15.513563 | F37: =Historicals!F14/Historicals!F16 -> 15.729904 | G37: =AVERAGE(B37:F37) -> 16.467173 | H37: =AVERAGE(D37:F37) -> 15.243039
A38: Free cash flow conversion (FCF / net income) | B38: =Historicals!B71/Historicals!B22 -> 0.80999049 | C38: =Historicals!C71/Historicals!C22 -> 1.0260274 | D38: =Historicals!D71/Historicals!D22 -> 0.97479208 | E38: =Historicals!E71/Historicals!E22 -> 0.65136859 | F38: =Historicals!F71/Historicals!F22 -> 0.6816334 | G38: =AVERAGE(B38:F38) -> 0.82876239 | H38: =AVERAGE(D38:F38) -> 0.76926469
A40: The three ratios follow the course convention: the PP&E and working capital balances are set against NEXT year capacity is in place before the sales it serves, and depreciation is charged on the OPENING balance. Ratios against next year revenue stop at FY2025, the last year with a following year in the data.

Sheet WACC
A1: Cost of Capital
A2: Market data as of September 15, 2026. Blue cells are inputs you can change.
A4: MARKET DATA
A5: Share price | B5: 108.09 | C5: Source: Yahoo Finance, WMT close, 9/15/2026
A6: Diluted shares outstanding (mm) | B6: 8022 | C6: Source: Yahoo Finance, FY2026 diluted weighted average shares
A7: Market capitalisation ($mm) | B7: =B5*B6 -> 867097.98
A8: Total financial debt ($mm) | B8: =Historicals!F55 -> 51523 | C8: Link: Historicals, FY2026
A9: Less: cash and cash equivalents ($mm) | B9: =-Historicals!F27 -> -10727
A10: Net debt ($mm) | B10: =B8+B9 -> 40796
A11: Noncontrolling interest ($mm) | B11: =Historicals!F49 -> 6563
A12: Enterprise value at market ($mm) | B12: =B7+B10+B11 -> 914456.98
A14: COST OF EQUITY (CAPM)
A15: Risk-free rate | B15: 0.0497 | C15: Source: FRED series DGS10, 10-year Treasury constant maturity, 9/14/2026
A16: Equity risk premium | B16: 0.05 | C16: Assumption: long-run US equity risk premium
A17: Levered beta | B17: 0.595 | C17: Source: Yahoo Finance, WMT beta (5-yr monthly vs. S&P 500)
A18: Cost of equity | B18: =B15+B17*B16 -> 0.07945
A20: COST OF DEBT
A21: Pre-tax cost of debt | B21: 0.053 | C21: Assumption: 10-yr Treasury plus c.35bp for WMT senior unsecured (AA rated)
A22: Marginal tax rate | B22: 0.25 | C22: Assumption: 21% federal plus state, consistent with recent effective rates
A23: After-tax cost of debt | B23: =B21*(1-B22) -> 0.03975
A24: Memo: FY2026 interest expense / average financial debt | B24: =Historicals!F16/AVERAGE(Historicals!E55:F55) -> 0.057525716 | C24: Backward-looking check on the input above; includes finance lease interest.
A26: CAPITAL STRUCTURE AND WACC
A27: Market value of equity | B27: =B7 -> 867097.98
A28: Total financial debt (book value as proxy for market value) | B28: =B8 -> 51523
A29: Total capital | B29: =B27+B28 -> 918620.98
A30: Weight of equity | B30: =B27/B29 -> 0.94391267
A31: Weight of debt | B31: =B28/B29 -> 0.056087332
A33: Weighted average cost of capital | B33: =B30*B18+B31*B23 -> 0.077223333 | C33: Key driver of the valuation. Test it on the Sensitivity sheet.
A35: Operating leases are excluded from debt and their rent is left inside EBIT, so the income statement and the debt bridge are on the same basis.

Sheet DCF
A1: Two-Stage Enterprise Valuation - Discounted Free Cash Flow to the Firm
A2: $ in millions. Fixed capital follows the course convention: the PP&E balance is set against next year revenue, depreciation is charged on the opening balance, and capital expenditure is the residual.
A4: Fiscal year ended January 31, | B4: FY2026A | C4: FY2027E | D4: FY2028E | E4: FY2029E | F4: FY2030E | G4: FY2031E | H4: Basis for the assumption
A6: STAGE 1 DRIVERS
A7: Revenue growth | C7: 0.045 | D7: 0.041 | E7: 0.037 | F7: 0.033 | G7: 0.03 | H7: FY2026 actual 4.7%, fading to the 3.0% terminal rate by FY2031.
A8: Operating margin (EBIT) | C8: 0.0425 | D8: 0.043 | E8: 0.0435 | F8: 0.044 | G8: 0.044 | H8: FY2026 4.18%; gentle expansion, then held flat in the steady-state year.
A9: Effective tax rate | C9: 0.25 | D9: 0.25 | E9: 0.25 | F9: 0.25 | G9: 0.25 | H9: FY2024-FY2026 average is 24.4%.
A10: Net PP&E as % of next year revenue (k) | C10: 0.19 | D10: 0.19 | E10: 0.19 | F10: 0.19 | G10: 0.19 | H10: FY2025 actual 17.7% and rising; 19.0% holds WMT at its current, elevated asset intensity.
A11: Depreciation as % of opening net PP&E (d) | C11: 0.112 | D11: 0.112 | E11: 0.112 | F11: 0.112 | G11: 0.112 | H11: FY2023-FY2026 actuals: 11.07%, 11.22%, 11.12%, 11.26%. An implied 8.9-year life.
A12: Non-cash additions to net PP&E ($mm) | C12: 1350 | D12: 1350 | E12: 1350 | F12: 1350 | G12: 1350 | H12: Finance lease additions, acquired PP&E, FX and disposals. Four-year average of the reconciling residual.
A13: Net working capital as % of next year revenue (w) | C13: -0.0275 | D13: -0.0275 | E13: -0.0275 | F13: -0.0275 | G13: -0.0275 | H13: FY2022-FY2025 actuals averaged -2.7%; growth releases cash.
A16: STAGE 1 FORECAST
A17: Revenue | B17: =Historicals!F7 -> 713163 | C17: =B17*(1+C7) -> 745255.33 | D17: =C17*(1+D7) -> 775810.8 | E17: =D17*(1+E7) -> 804515.8 | F17: =E17*(1+F7) -> 831064.82 | G17: =F17*(1+G7) -> 855996.77
A18: Next year revenue | B18: =C17 -> 745255.33 | C18: =D17 -> 775810.8 | D18: =E17 -> 804515.8 | E18: =F17 -> 831064.82 | F18: =G17 -> 855996.77 | G18: =G17*(1+$C$59) -> 881676.67 | H18: FY2031 grows at the terminal rate, making it the steady-state year.
A19: Operating income (EBIT) | B19: =Historicals!F11 -> 29825 | C19: =C17*C8 -> 31673.352 | D19: =D17*D8 -> 33359.865 | E19: =E17*E8 -> 34996.437 | F19: =F17*F8 -> 36566.852 | G19: =G17*G8 -> 37663.858
A20: Less: taxes on EBIT | B20: =-B19*Historicals!F19/Historicals!F18 -> -7285.9675 | C20: =-C19*C9 -> -7918.3379 | D20: =-D19*D9 -> -8339.9661 | E20: =-E19*E9 -> -8749.1094 | F20: =-F19*F9 -> -9141.7131 | G20: =-G19*G9 -> -9415.9645
A21: Net operating profit after tax (NOPAT) | B21: =B19+B20 -> 22539.033 | C21: =C19+C20 -> 23755.014 | D21: =D19+D20 -> 25019.898 | E21: =E19+E20 -> 26247.328 | F21: =F19+F20 -> 27425.139 | G21: =G19+G20 -> 28247.893
A23: PROPERTY AND EQUIPMENT ROLL-FORWARD
A24: Net PP&E, beginning of year | B24: =Historicals!E32 -> 126105 | C24: =B28 -> 142206 | D24: =C28 -> 147404.05 | E24: =D28 -> 152858 | F24: =E28 -> 157902.32 | G24: =F28 -> 162639.39
A25: Plus: capital expenditures (RESIDUAL) | B25: =Historicals!F70 -> 26642 | C25: =C28-C24-C26-C27 -> 19775.125 | D25: =D28-D24-D26-D27 -> 20613.204 | E25: =E28-E24-E26-E27 -> 20814.41 | F25: =F28-F24-F26-F27 -> 21072.129 | G25: =G28-G24-G26-G27 -> 21744.793 | H25: Funds the increase in the balance and replaces what was depreciated.
A26: Plus: non-cash additions (finance leases, M&A, FX) | B26: =Historicals!F74 -> 3662 | C26: =C12 -> 1350 | D26: =D12 -> 1350 | E26: =E12 -> 1350 | F26: =F12 -> 1350 | G26: =G12 -> 1350
A27: Less: depreciation | B27: =-Historicals!F13 -> -14203 | C27: =-C11*C24 -> -15927.072 | D27: =-D11*D24 -> -16509.254 | E27: =-E11*E24 -> -17120.096 | F27: =-F11*F24 -> -17685.059 | G27: =-G11*G24 -> -18215.611 | H27: Charged on the OPENING balance, per the course convention.
A28: Net PP&E, end of year | B28: =Historicals!F32 -> 142206 | C28: =C10*C18 -> 147404.05 | D28: =D10*D18 -> 152858 | E28: =E10*E18 -> 157902.32 | F28: =F10*F18 -> 162639.39 | G28: =G10*G18 -> 167518.57 | H28: Set by k times next year revenue: capacity is in place before the sales it serves.
A29: Memo: implied capex % of revenue | B29: =B25/B17 -> 0.037357519 | C29: =C25/C17 -> 0.026534697 | D29: =D25/D17 -> 0.026569885 | E29: =E25/E17 -> 0.025871972 | F29: =F25/F17 -> 0.025355578 | G29: =G25/G17 -> 0.025402891 | H29: Output of the three ratios. FY2022-FY2026 actuals ran 2.3% to 3.7%.
A30: Memo: implied capex / depreciation | B30: =-B25/B27 -> 1.8758009 | C30: =-C25/C27 -> 1.2416045 | D30: =-D25/D27 -> 1.2485848 | E30: =-E25/E27 -> 1.2157882 | F30: =-F25/F27 -> 1.1915215 | G30: =-G25/G27 -> 1.1937449
A31: Memo: EBITDA | B31: =B19-B27 -> 44028 | C31: =C19-C27 -> 47600.424 | D31: =D19-D27 -> 49869.118 | E31: =E19-E27 -> 52116.534 | F31: =F19-F27 -> 54251.912 | G31: =G19-G27 -> 55879.469
A33: INVESTED CAPITAL
A34: Net working capital | B34: =Historicals!F59 -> -20697 | C34: =C13*C18 -> -21334.797 | D34: =D13*D18 -> -22124.185 | E34: =E13*E18 -> -22854.283 | F34: =F13*F18 -> -23539.911 | G34: =G13*G18 -> -24246.109
A35: Net PP&E | B35: =Historicals!F32 -> 142206 | C35: =C28 -> 147404.05 | D35: =D28 -> 152858 | E35: =E28 -> 157902.32 | F35: =F28 -> 162639.39 | G35: =G28 -> 167518.57
A36: Goodwill | B36: =Historicals!F34 -> 28735 | C36: =B36 -> 28735 | D36: =C36 -> 28735 | E36: =D36 -> 28735 | F36: =E36 -> 28735 | G36: =F36 -> 28735 | H36: Held flat: goodwill does not depreciate and this is an organic forecast.
A37: Operating lease ROU net of lease liabilities | B37: =Historicals!F62 -> -822 | C37: =B37 -> -822 | D37: =C37 -> -822 | E37: =D37 -> -822 | F37: =E37 -> -822 | G37: =F37 -> -822 | H37: Held flat; the asset and liability substantially offset.
A38: Net other long-term assets/(liabilities) | B38: =Historicals!F63 -> -2446 | C38: =B38 -> -2446 | D38: =C38 -> -2446 | E38: =D38 -> -2446 | F38: =E38 -> -2446 | G38: =F38 -> -2446 | H38: Held flat and treated as non-operating: carried at book value in the bridge below.
A39: Invested capital | B39: =SUM(B34:B38) -> 146976 | C39: =SUM(C34:C38) -> 151536.26 | D39: =SUM(D34:D38) -> 156200.82 | E39: =SUM(E34:E38) -> 160515.03 | F39: =SUM(F34:F38) -> 164566.48 | G39: =SUM(G34:G38) -> 168739.46
A40: Increase in invested capital | B40: =B39-Historicals!E64 -> 12531 | C40: =C39-B39 -> 4560.2556 | D40: =D39-C39 -> 4664.5625 | E40: =E39-D39 -> 4314.216 | F40: =F39-E39 -> 4051.441 | G40: =G39-F39 -> 4172.9843
A41: Memo: return on invested capital | B41: =B21/B39 -> 0.15335179 | C41: =C21/C39 -> 0.15676126 | D41: =D21/D39 -> 0.16017777 | E41: =E21/E39 -> 0.16351944 | F41: =F21/F39 -> 0.16665083 | G41: =G21/G39 -> 0.16740538 | H41: NOPAT / invested capital. Historic range 15-17%.
A43: FREE CASH FLOW TO THE FIRM
A44: NOPAT | B44: =B21 -> 22539.033 | C44: =C21 -> 23755.014 | D44: =D21 -> 25019.898 | E44: =E21 -> 26247.328 | F44: =F21 -> 27425.139 | G44: =G21 -> 28247.893
A45: Plus: depreciation | B45: =-B27 -> 14203 | C45: =-C27 -> 15927.072 | D45: =-D27 -> 16509.254 | E45: =-E27 -> 17120.096 | F45: =-F27 -> 17685.059 | G45: =-G27 -> 18215.611
A46: Less: capital expenditures | B46: =-B25 -> -26642 | C46: =-C25 -> -19775.125 | D46: =-D25 -> -20613.204 | E46: =-E25 -> -20814.41 | F46: =-F25 -> -21072.129 | G46: =-G25 -> -21744.793
A47: Less: increase in net working capital | B47: =-(B34-Historicals!E59) -> 2499 | C47: =-(C34-B34) -> 637.7971 | D47: =-(D34-C34) -> 789.38749 | E47: =-(E34-D34) -> 730.09809 | F47: =-(F34-E34) -> 685.62848 | G47: =-(G34-F34) -> 706.19734
...

Sheet Sensitivity
A1: Sensitivity and Reverse DCF
A2: Value per share across discount rate, terminal growth and asset intensity, and the growth the current price already implies.
A4: IMPLIED VALUE PER SHARE - WACC VERSUS TERMINAL GROWTH
A6: WACC (down) versus terminal growth rate (across)
B7: WACC | C7: 0.02 | D7: 0.025 | E7: 0.03 | F7: 0.035 | G7: 0.04
B8: 0.065 | C8: =IF($B8<=$C$7,"n/m",(NPV($B8,DCF!$C$49:$G$49)+DCF!$G$49*(1+C$7)/($B8-C$7)/(1+$B8)^5-Historicals!$F$55+Historicals!$F$27+Historicals!$F$63-Historicals!$F$49)/WACC!$B$6) -> 58.127867 | D8: =IF($B8<=$D$7,"n/m",(NPV($B8,DCF!$C$49:$G$49)+DCF!$G$49*(1+D$7)/($B8-D$7)/(1+$B8)^5-Historicals!$F$55+Historicals!$F$27+Historicals!$F$63-Historicals!$F$49)/WACC!$B$6) -> 64.971328 | E8: =IF($B8<=$E$7,"n/m",(NPV($B8,DCF!$C$49:$G$49)+DCF!$G$49*(1+E$7)/($B8-E$7)/(1+$B8)^5-Historicals!$F$55+Historicals!$F$27+Historicals!$F$63-Historicals!$F$49)/WACC!$B$6) -> 73.770064 | F8: =IF($B8<=$F$7,"n/m",(NPV($B8,DCF!$C$49:$G$49)+DCF!$G$49*(1+F$7)/($B8-F$7)/(1+$B8)^5-Historicals!$F$55+Historicals!$F$27+Historicals!$F$63-Historicals!$F$49)/WACC!$B$6) -> 85.501712 | G8: =IF($B8<=$G$7,"n/m",(NPV($B8,DCF!$C$49:$G$49)+DCF!$G$49*(1+G$7)/($B8-G$7)/(1+$B8)^5-Historicals!$F$55+Historicals!$F$27+Historicals!$F$63-Historicals!$F$49)/WACC!$B$6) -> 101.92602
B9: 0.07 | C9: =IF($B9<=$C$7,"n/m",(NPV($B9,DCF!$C$49:$G$49)+DCF!$G$49*(1+C$7)/($B9-C$7)/(1+$B9)^5-Historicals!$F$55+Historicals!$F$27+Historicals!$F$63-Historicals!$F$49)/WACC!$B$6) -> 51.627071 | D9: =IF($B9<=$D$7,"n/m",(NPV($B9,DCF!$C$49:$G$49)+DCF!$G$49*(1+D$7)/($B9-D$7)/(1+$B9)^5-Historicals!$F$55+Historicals!$F$27+Historicals!$F$63-Historicals!$F$49)/WACC!$B$6) -> 57.000223 | E9: =IF($B9<=$E$7,"n/m",(NPV($B9,DCF!$C$49:$G$49)+DCF!$G$49*(1+E$7)/($B9-E$7)/(1+$B9)^5-Historicals!$F$55+Historicals!$F$27+Historicals!$F$63-Historicals!$F$49)/WACC!$B$6) -> 63.716663 | F9: =IF($B9<=$F$7,"n/m",(NPV($B9,DCF!$C$49:$G$49)+DCF!$G$49*(1+F$7)/($B9-F$7)/(1+$B9)^5-Historicals!$F$55+Historicals!$F$27+Historicals!$F$63-Historicals!$F$49)/WACC!$B$6) -> 72.352086 | G9: =IF($B9<=$G$7,"n/m",(NPV($B9,DCF!$C$49:$G$49)+DCF!$G$49*(1+G$7)/($B9-G$7)/(1+$B9)^5-Historicals!$F$55+Historicals!$F$27+Historicals!$F$63-Historicals!$F$49)/WACC!$B$6) -> 83.865983
B10: 0.075 | C10: =IF($B10<=$C$7,"n/m",(NPV($B10,DCF!$C$49:$G$49)+DCF!$G$49*(1+C$7)/($B10-C$7)/(1+$B10)^5-Historicals!$F$55+Historicals!$F$27+Historicals!$F$63-Historicals!$F$49)/WACC!$B$6) -> 46.309233 | D10: =IF($B10<=$D$7,"n/m",(NPV($B10,DCF!$C$49:$G$49)+DCF!$G$49*(1+D$7)/($B10-D$7)/(1+$B10)^5-Historicals!$F$55+Historicals!$F$27+Historicals!$F$63-Historicals!$F$49)/WACC!$B$6) -> 50.624227 | E10: =IF($B10<=$E$7,"n/m",(NPV($B10,DCF!$C$49:$G$49)+DCF!$G$49*(1+E$7)/($B10-E$7)/(1+$B10)^5-Historicals!$F$55+Historicals!$F$27+Historicals!$F$63-Historicals!$F$49)/WACC!$B$6) -> 55.898109 | F10: =IF($B10<=$F$7,"n/m",(NPV($B10,DCF!$C$49:$G$49)+DCF!$G$49*(1+F$7)/($B10-F$7)/(1+$B10)^5-Historicals!$F$55+Historicals!$F$27+Historicals!$F$63-Historicals!$F$49)/WACC!$B$6) -> 62.490461 | G10: =IF($B10<=$G$7,"n/m",(NPV($B10,DCF!$C$49:$G$49)+DCF!$G$49*(1+G$7)/($B10-G$7)/(1+$B10)^5-Historicals!$F$55+Historicals!$F$27+Historicals!$F$63-Historicals!$F$49)/WACC!$B$6) -> 70.966342
B11: 0.0772 | C11: =IF($B11<=$C$7,"n/m",(NPV($B11,DCF!$C$49:$G$49)+DCF!$G$49*(1+C$7)/($B11-C$7)/(1+$B11)^5-Historicals!$F$55+Historicals!$F$27+Historicals!$F$63-Historicals!$F$49)/WACC!$B$6) -> 44.264209 | D11: =IF($B11<=$D$7,"n/m",(NPV($B11,DCF!$C$49:$G$49)+DCF!$G$49*(1+D$7)/($B11-D$7)/(1+$B11)^5-Historicals!$F$55+Historicals!$F$27+Historicals!$F$63-Historicals!$F$49)/WACC!$B$6) -> 48.206011 | E11: =IF($B11<=$E$7,"n/m",(NPV($B11,DCF!$C$49:$G$49)+DCF!$G$49*(1+E$7)/($B11-E$7)/(1+$B11)^5-Historicals!$F$55+Historicals!$F$27+Historicals!$F$63-Historicals!$F$49)/WACC!$B$6) -> 52.982941 | F11: =IF($B11<=$F$7,"n/m",(NPV($B11,DCF!$C$49:$G$49)+DCF!$G$49*(1+F$7)/($B11-F$7)/(1+$B11)^5-Historicals!$F$55+Historicals!$F$27+Historicals!$F$63-Historicals!$F$49)/WACC!$B$6) -> 58.891845 | G11: =IF($B11<=$G$7,"n/m",(NPV($B11,DCF!$C$49:$G$49)+DCF!$G$49*(1+G$7)/($B11-G$7)/(1+$B11)^5-Historicals!$F$55+Historicals!$F$27+Historicals!$F$63-Historicals!$F$49)/WACC!$B$6) -> 66.389164
B12: 0.08 | C12: =IF($B12<=$C$7,"n/m",(NPV($B12,DCF!$C$49:$G$49)+DCF!$G$49*(1+C$7)/($B12-C$7)/(1+$B12)^5-Historicals!$F$55+Historicals!$F$27+Historicals!$F$63-Historicals!$F$49)/WACC!$B$6) -> 41.878594 | D12: =IF($B12<=$D$7,"n/m",(NPV($B12,DCF!$C$49:$G$49)+DCF!$G$49*(1+D$7)/($B12-D$7)/(1+$B12)^5-Historicals!$F$55+Historicals!$F$27+Historicals!$F$63-Historicals!$F$49)/WACC!$B$6) -> 45.408294 | E12: =IF($B12<=$E$7,"n/m",(NPV($B12,DCF!$C$49:$G$49)+DCF!$G$49*(1+E$7)/($B12-E$7)/(1+$B12)^5-Historicals!$F$55+Historicals!$F$27+Historicals!$F$63-Historicals!$F$49)/WACC!$B$6) -> 49.643934 | F12: =IF($B12<=$F$7,"n/m",(NPV($B12,DCF!$C$49:$G$49)+DCF!$G$49*(1+F$7)/($B12-F$7)/(1+$B12)^5-Historicals!$F$55+Historicals!$F$27+Historicals!$F$63-Historicals!$F$49)/WACC!$B$6) -> 54.820827 | G12: =IF($B12<=$G$7,"n/m",(NPV($B12,DCF!$C$49:$G$49)+DCF!$G$49*(1+G$7)/($B12-G$7)/(1+$B12)^5-Historicals!$F$55+Historicals!$F$27+Historicals!$F$63-Historicals!$F$49)/WACC!$B$6) -> 61.291944
B13: 0.085 | C13: =IF($B13<=$C$7,"n/m",(NPV($B13,DCF!$C$49:$G$49)+DCF!$G$49*(1+C$7)/($B13-C$7)/(1+$B13)^5-Historicals!$F$55+Historicals!$F$27+Historicals!$F$63-Historicals!$F$49)/WACC!$B$6) -> 38.130397 | D13: =IF($B13<=$D$7,"n/m",(NPV($B13,DCF!$C$49:$G$49)+DCF!$G$49*(1+D$7)/($B13-D$7)/(1+$B13)^5-Historicals!$F$55+Historicals!$F$27+Historicals!$F$63-Historicals!$F$49)/WACC!$B$6) -> 41.062392 | E13: =IF($B13<=$E$7,"n/m",(NPV($B13,DCF!$C$49:$G$49)+DCF!$G$49*(1+E$7)/($B13-E$7)/(1+$B13)^5-Historicals!$F$55+Historicals!$F$27+Historicals!$F$63-Historicals!$F$49)/WACC!$B$6) -> 44.527476 | F13: =IF($B13<=$F$7,"n/m",(NPV($B13,DCF!$C$49:$G$49)+DCF!$G$49*(1+F$7)/($B13-F$7)/(1+$B13)^5-Historicals!$F$55+Historicals!$F$27+Historicals!$F$63-Historicals!$F$49)/WACC!$B$6) -> 48.685578 | G13: =IF($B13<=$G$7,"n/m",(NPV($B13,DCF!$C$49:$G$49)+DCF!$G$49*(1+G$7)/($B13-G$7)/(1+$B13)^5-Historicals!$F$55+Historicals!$F$27+Historicals!$F$63-Historicals!$F$49)/WACC!$B$6) -> 53.767702
B14: 0.09 | C14: =IF($B14<=$C$7,"n/m",(NPV($B14,DCF!$C$49:$G$49)+DCF!$G$49*(1+C$7)/($B14-C$7)/(1+$B14)^5-Historicals!$F$55+Historicals!$F$27+Historicals!$F$63-Historicals!$F$49)/WACC!$B$6) -> 34.918388 | D14: =IF($B14<=$D$7,"n/m",(NPV($B14,DCF!$C$49:$G$49)+DCF!$G$49*(1+D$7)/($B14-D$7)/(1+$B14)^5-Historicals!$F$55+Historicals!$F$27+Historicals!$F$63-Historicals!$F$49)/WACC!$B$6) -> 37.385731 | E14: =IF($B14<=$E$7,"n/m",(NPV($B14,DCF!$C$49:$G$49)+DCF!$G$49*(1+E$7)/($B14-E$7)/(1+$B14)^5-Historicals!$F$55+Historicals!$F$27+Historicals!$F$63-Historicals!$F$49)/WACC!$B$6) -> 40.264296 | F14: =IF($B14<=$F$7,"n/m",(NPV($B14,DCF!$C$49:$G$49)+DCF!$G$49*(1+F$7)/($B14-F$7)/(1+$B14)^5-Historicals!$F$55+Historicals!$F$27+Historicals!$F$63-Historicals!$F$49)/WACC!$B$6) -> 43.666238 | G14: =IF($B14<=$G$7,"n/m",(NPV($B14,DCF!$C$49:$G$49)+DCF!$G$49*(1+G$7)/($B14-G$7)/(1+$B14)^5-Historicals!$F$55+Historicals!$F$27+Historicals!$F$63-Historicals!$F$49)/WACC!$B$6) -> 47.748567
A16: Each cell rebuilds the valuation from the Stage 1 cash flows on the DCF sheet, which do not themselves depend on WACC or terminal growth.
A19: REVERSE DCF - WHAT THE CURRENT PRICE IMPLIES
A20: Enterprise value at the current share price | B20: =WACC!$B$12 -> 914456.98 | C20: Market capitalisation plus net debt plus noncontrolling interest.
A21: Less: present value of Stage 1 free cash flows | B21: =-DCF!$C$69 -> -92291.702
A22: Implied present value of the terminal value | B22: =B20+B21 -> 822165.28
A23: Implied terminal value at end of FY2031 | B23: =B22/DCF!$G$54 -> 1192581
A24: Terminal year (FY2031) free cash flow | B24: =DCF!$G$49 -> 25424.909
A25: Implied perpetual growth rate | B25: =(B23*WACC!$B$33-B24)/(B24+B23) -> 0.054737149 | C25: g solving TV = FCF x (1+g) / (r - g).
A26: Implied exit EV / EBITDA multiple | B26: =B23/DCF!$G$31 -> 21.342025 | C26: Versus c.20x today and the 12x assumed on the DCF sheet.
A27: Memo: terminal growth rate assumed in the DCF | B27: =DCF!$C$59 -> 0.03
A29: If the implied growth rate exceeds long-run nominal GDP growth (c.4%), the market is assuming permanently faster growth, wider margins, or lower capital intensity than the Stage 1 forecast.
A31: VALUE PER SHARE VERSUS ASSET INTENSITY (k)
A33: Depreciation cancels out of free cash flow. Substituting the residual, capex less depreciation is just the change in the PP&E balance, so FCF = NOPAT - increase in PP&E + non-cash additions - increase in working capital. The k ratio therefore drives fixed-capital cash flow on its own; the depreciation rate d only matters through EBIT and tax. WMT has run k from 16.2% up to 17.7% and the base case holds it at 19.0%.
A36: Free cash flow at each asset-intensity assumption | B36: k | C36: FY2027E | D36: FY2028E | E36: FY2029E | F36: FY2030E | G36: FY2031E | H36: Value per share
B37: 0.175 | C37: =DCF!C$21-(DCF!C$18*$B37-DCF!$B$28)+DCF!C$12-(DCF!C$34-DCF!B$34) -> 32181.92 | D37: =DCF!D$21-(DCF!D$18*$B37-DCF!C$18*$B37)+DCF!D$12-(DCF!D$34-DCF!C$34) -> 22135.911 | E37: =DCF!E$21-(DCF!E$18*$B37-DCF!D$18*$B37)+DCF!E$12-(DCF!E$34-DCF!D$34) -> 23681.347 | F37: =DCF!F$21-(DCF!F$18*$B37-DCF!E$18*$B37)+DCF!F$12-(DCF!F$34-DCF!E$34) -> 25097.677 | G37: =DCF!G$21-(DCF!G$18*$B37-DCF!F$18*$B37)+DCF!G$12-(DCF!G$34-DCF!F$34) -> 25810.108 | H37: =(NPV(WACC!$B$33,C37:G37)+G37*(1+DCF!$C$59)/(WACC!$B$33-DCF!$C$59)/(1+WACC!$B$33)^5-Historicals!$F$55+Historicals!$F$27+Historicals!$F$63-Historicals!$F$49)/WACC!$B$6 -> 55.175862 | I37: Back to the FY2025 level
B38: 0.182 | C38: =DCF!C$21-(DCF!C$18*$B38-DCF!$B$28)+DCF!C$12-(DCF!C$34-DCF!B$34) -> 26751.245 | D38: =DCF!D$21-(DCF!D$18*$B38-DCF!C$18*$B38)+DCF!D$12-(DCF!D$34-DCF!C$34) -> 21934.976 | E38: =DCF!E$21-(DCF!E$18*$B38-DCF!D$18*$B38)+DCF!E$12-(DCF!E$34-DCF!D$34) -> 23495.504 | F38: =DCF!F$21-(DCF!F$18*$B38-DCF!E$18*$B38)+DCF!F$12-(DCF!F$34-DCF!E$34) -> 24923.154 | G38: =DCF!G$21-(DCF!G$18*$B38-DCF!F$18*$B38)+DCF!G$12-(DCF!G$34-DCF!F$34) -> 25630.348 | H38: =(NPV(WACC!$B$33,C38:G38)+G38*(1+DCF!$C$59)/(WACC!$B$33-DCF!$C$59)/(1+WACC!$B$33)^5-Historicals!$F$55+Historicals!$F$27+Historicals!$F$63-Historicals!$F$49)/WACC!$B$6 -> 54.13875 | I38: Partial unwind of the build-out
B39: 0.19 | C39: =DCF!C$21-(DCF!C$18*$B39-DCF!$B$28)+DCF!C$12-(DCF!C$34-DCF!B$34) -> 20544.758 | D39: =DCF!D$21-(DCF!D$18*$B39-DCF!C$18*$B39)+DCF!D$12-(DCF!D$34-DCF!C$34) -> 21705.336 | E39: =DCF!E$21-(DCF!E$18*$B39-DCF!D$18*$B39)+DCF!E$12-(DCF!E$34-DCF!D$34) -> 23283.112 | F39: =DCF!F$21-(DCF!F$18*$B39-DCF!E$18*$B39)+DCF!F$12-(DCF!F$34-DCF!E$34) -> 24723.698 | G39: =DCF!G$21-(DCF!G$18*$B39-DCF!F$18*$B39)+DCF!G$12-(DCF!G$34-DCF!F$34) -> 25424.909 | H39: =(NPV(WACC!$B$33,C39:G39)+G39*(1+DCF!$C$59)/(WACC!$B$33-DCF!$C$59)/(1+WACC!$B$33)^5-Historicals!$F$55+Historicals!$F$27+Historicals!$F$63-Historicals!$F$49)/WACC!$B$6 -> 52.95348 | I39: Base case: intensity holds at the current level
B40: 0.198 | C40: =DCF!C$21-(DCF!C$18*$B40-DCF!$B$28)+DCF!C$12-(DCF!C$34-DCF!B$34) -> 14338.272 | D40: =DCF!D$21-(DCF!D$18*$B40-DCF!C$18*$B40)+DCF!D$12-(DCF!D$34-DCF!C$34) -> 21475.696 | E40: =DCF!E$21-(DCF!E$18*$B40-DCF!D$18*$B40)+DCF!E$12-(DCF!E$34-DCF!D$34) -> 23070.72 | F40: =DCF!F$21-(DCF!F$18*$B40-DCF!E$18*$B40)+DCF!F$12-(DCF!F$34-DCF!E$34) -> 24524.243 | G40: =DCF!G$21-(DCF!G$18*$B40-DCF!F$18*$B40)+DCF!G$12-(DCF!G$34-DCF!F$34) -> 25219.47 | H40: =(NPV(WACC!$B$33,C40:G40)+G40*(1+DCF!$C$59)/(WACC!$B$33-DCF!$C$59)/(1+WACC!$B$33)^5-Historicals!$F$55+Historicals!$F$27+Historicals!$F$63-Historicals!$F$49)/WACC!$B$6 -> 51.768209 | I40: Intensity keeps rising
B41: 0.206 | C41: =DCF!C$21-(DCF!C$18*$B41-DCF!$B$28)+DCF!C$12-(DCF!C$34-DCF!B$34) -> 8131.7853 | D41: =DCF!D$21-(DCF!D$18*$B41-DCF!C$18*$B41)+DCF!D$12-(DCF!D$34-DCF!C$34) -> 21246.056 | E41: =DCF!E$21-(DCF!E$18*$B41-DCF!D$18*$B41)+DCF!E$12-(DCF!E$34-DCF!D$34) -> 22858.328 | F41: =DCF!F$21-(DCF!F$18*$B41-DCF!E$18*$B41)+DCF!F$12-(DCF!F$34-DCF!E$34) -> 24324.787 | G41: =DCF!G$21-(DCF!G$18*$B41-DCF!F$18*$B41)+DCF!G$12-(DCF!G$34-DCF!F$34) -> 25014.031 | H41: =(NPV(WACC!$B$33,C41:G41)+G41*(1+DCF!$C$59)/(WACC!$B$33-DCF!$C$59)/(1+WACC!$B$33)^5-Historicals!$F$55+Historicals!$F$27+Historicals!$F$63-Historicals!$F$49)/WACC!$B$6 -> 50.582938 | I41: The build-out continues at the recent pace
A43: Uses the base-case WACC and terminal growth. A higher k means more plant per dollar of sales, higher capital expenditure, and less free cash flow.
